<mujoco model="roomba_uwb">
    <option iterations="8" ls_iterations="16" solver="Newton" timestep="0.002"/>
    <include file="common/assets_defaults.xml"/>
    <worldbody>
        <geom name="floor" type="mesh" mesh="oct_floor" pos="0 0 0" quat="0.7071 0.7071 0 0" material="floor_color" friction="2.0 0.02 0.001"/>        
        <light name="light" pos="0 0 7" dir="0 0 -1" mode="fixed"/>
        <camera name="side" pos="-4 0 2" xyaxes="0 -1 0 1 0 2" mode="fixed"/>
        <body name="roomba1" pos="0 0.5 0.2">
            <freejoint name="root1"/>
            <geom name="roomba1" type="cylinder" size="0.1625 0.035" pos="0 0 0" material="roomba1_color"/>
            <body name="lwheel1" pos="0.115 0.005 -0.005">
                <joint name="lwheel1" type="hinge" axis="1 0 0"/>
                <geom type="cylinder" size="0.04 0.015" quat="0 0.7071 0 0.7071" friction="2.0 0.02 0.001"/>
            </body>
            <body name="rwheel1" pos="-0.115 0.005 -0.005">
                <joint name="rwheel1" type="hinge" axis="1 0 0"/>
                <geom type="cylinder" size="0.04 0.015" quat="0 0.7071 0 0.7071" friction="2.0 0.02 0.001"/>
            </body>
            <body name="fwheel1" pos="0 -0.13 -0.025">
                <geom type="sphere" size="0.02" friction="0 0 0"/>
            </body>
            <body name="fsensor1" pos="0 -0.13 0.02">
                <geom type="cylinder" size="0.015 0.02" material="roomba1_decal_color" contype="0" conaffinity="0"/>
            </body>
            <body name="onbutton1" pos="0 0 0.02">
                <geom type="cylinder" size="0.03 0.02" material="roomba1_decal_color" contype="0" conaffinity="0"/>
            </body>
        </body>
        <body name="roomba2" pos="0 -0.5 0.2" quat="0 0 0 1">
            <freejoint name="root2"/>
            <geom name="roomba2" type="cylinder" size="0.1625 0.035" pos="0 0 0" material="roomba2_color"/>
            <body name="lwheel2" pos="0.115 0.005 -0.005">
                <joint name="lwheel2" type="hinge" axis="1 0 0"/>
                <geom type="cylinder" size="0.04 0.015" quat="0 0.7071 0 0.7071"  friction="2.0 0.02 0.001"/>
            </body>
            <body name="rwheel2" pos="-0.115 0.005 -0.005">
                <joint name="rwheel2" type="hinge" axis="1 0 0"/>
                <geom type="cylinder" size="0.04 0.015" quat="0 0.7071 0 0.7071"  friction="2.0 0.02 0.001"/>
            </body>
            <body name="fwheel2" pos="0 -0.13 -0.025">
                <geom type="sphere" size="0.02" friction="0 0 0"/>
            </body>
            <body name="fsensor2" pos="0 -0.13 0.02">
                <geom type="cylinder" size="0.015 0.02" material="roomba2_decal_color" contype="0" conaffinity="0"/>
            </body>
            <body name="onbutton2" pos="0 0 0.02">
                <geom type="cylinder" size="0.03 0.02" material="roomba2_decal_color" contype="0" conaffinity="0"/>
            </body>
        </body>
    </worldbody>

    <actuator>
        <motor name="lwheel1" joint="lwheel1" gear="3.2"/>
        <motor name="rwheel1" joint="rwheel1" gear="3.2"/>
        <motor name="lwheel2" joint="lwheel2" gear="3.2"/>
        <motor name="rwheel2" joint="rwheel2" gear="3.2"/>
    </actuator>
</mujoco>